TensorFlow installation not found - running with reduced feature set.

NOTE: Using experimental fast data loading logic. To disable, pass
    "--load_fast=false" and report issues on GitHub. More details:
    https://github.com/tensorflow/tensorboard/issues/4784

TensorBoard 2.14.0 at http://f21734f543a3:8888/ (Press CTRL+C to quit)
E1105 17:34:03.788079 140308813633088 _internal.py:97] Error on request:
Traceback (most recent call last):
  File "/root/miniconda3/envs/USB/lib/python3.8/site-packages/werkzeug/serving.py", line 370, in run_wsgi
    execute(self.server.app)
  File "/root/miniconda3/envs/USB/lib/python3.8/site-packages/werkzeug/serving.py", line 331, in execute
    application_iter = app(environ, start_response)
  File "/root/miniconda3/envs/USB/lib/python3.8/site-packages/tensorboard/backend/application.py", line 528, in __call__
    return self._app(environ, start_response)
  File "/root/miniconda3/envs/USB/lib/python3.8/site-packages/tensorboard/backend/application.py", line 569, in wrapper
    return wsgi_app(environ, start_response)
  File "/root/miniconda3/envs/USB/lib/python3.8/site-packages/tensorboard/backend/security_validator.py", line 91, in __call__
    return self._application(environ, start_response_proxy)
  File "/root/miniconda3/envs/USB/lib/python3.8/site-packages/tensorboard/backend/path_prefix.py", line 68, in __call__
    return self._application(environ, start_response)
  File "/root/miniconda3/envs/USB/lib/python3.8/site-packages/tensorboard/backend/experiment_id.py", line 73, in __call__
    return self._application(environ, start_response)
  File "/root/miniconda3/envs/USB/lib/python3.8/site-packages/tensorboard/backend/empty_path_redirect.py", line 43, in __call__
    return self._application(environ, start_response)
  File "/root/miniconda3/envs/USB/lib/python3.8/site-packages/tensorboard/backend/client_feature_flags.py", line 55, in __call__
    return self._application(environ, start_response)
  File "/root/miniconda3/envs/USB/lib/python3.8/site-packages/tensorboard/backend/auth_context_middleware.py", line 38, in __call__
    return self._application(environ, start_response)
  File "/root/miniconda3/envs/USB/lib/python3.8/site-packages/tensorboard/backend/application.py", line 551, in _route_request
    return self.exact_routes[clean_path](environ, start_response)
  File "/root/miniconda3/envs/USB/lib/python3.8/site-packages/werkzeug/wrappers/request.py", line 190, in application
    resp = f(*args[:-2] + (request,))
  File "/root/miniconda3/envs/USB/lib/python3.8/site-packages/tensorboard/plugins/hparams/hparams_plugin.py", line 122, in get_experiment_route
    json_format.MessageToJson(
TypeError: MessageToJson() got an unexpected keyword argument 'including_default_value_fields'
E1106 09:20:08.935712 140308712953408 _internal.py:97] Error on request:
Traceback (most recent call last):
  File "/root/miniconda3/envs/USB/lib/python3.8/site-packages/werkzeug/serving.py", line 370, in run_wsgi
    execute(self.server.app)
  File "/root/miniconda3/envs/USB/lib/python3.8/site-packages/werkzeug/serving.py", line 331, in execute
    application_iter = app(environ, start_response)
  File "/root/miniconda3/envs/USB/lib/python3.8/site-packages/tensorboard/backend/application.py", line 528, in __call__
    return self._app(environ, start_response)
  File "/root/miniconda3/envs/USB/lib/python3.8/site-packages/tensorboard/backend/application.py", line 569, in wrapper
    return wsgi_app(environ, start_response)
  File "/root/miniconda3/envs/USB/lib/python3.8/site-packages/tensorboard/backend/security_validator.py", line 91, in __call__
    return self._application(environ, start_response_proxy)
  File "/root/miniconda3/envs/USB/lib/python3.8/site-packages/tensorboard/backend/path_prefix.py", line 68, in __call__
    return self._application(environ, start_response)
  File "/root/miniconda3/envs/USB/lib/python3.8/site-packages/tensorboard/backend/experiment_id.py", line 73, in __call__
    return self._application(environ, start_response)
  File "/root/miniconda3/envs/USB/lib/python3.8/site-packages/tensorboard/backend/empty_path_redirect.py", line 43, in __call__
    return self._application(environ, start_response)
  File "/root/miniconda3/envs/USB/lib/python3.8/site-packages/tensorboard/backend/client_feature_flags.py", line 55, in __call__
    return self._application(environ, start_response)
  File "/root/miniconda3/envs/USB/lib/python3.8/site-packages/tensorboard/backend/auth_context_middleware.py", line 38, in __call__
    return self._application(environ, start_response)
  File "/root/miniconda3/envs/USB/lib/python3.8/site-packages/tensorboard/backend/application.py", line 551, in _route_request
    return self.exact_routes[clean_path](environ, start_response)
  File "/root/miniconda3/envs/USB/lib/python3.8/site-packages/werkzeug/wrappers/request.py", line 190, in application
    resp = f(*args[:-2] + (request,))
  File "/root/miniconda3/envs/USB/lib/python3.8/site-packages/tensorboard/plugins/hparams/hparams_plugin.py", line 122, in get_experiment_route
    json_format.MessageToJson(
TypeError: MessageToJson() got an unexpected keyword argument 'including_default_value_fields'
E1110 22:28:28.919774 140308763293248 _internal.py:97] Error on request:
Traceback (most recent call last):
  File "/root/miniconda3/envs/USB/lib/python3.8/site-packages/werkzeug/serving.py", line 370, in run_wsgi
    execute(self.server.app)
  File "/root/miniconda3/envs/USB/lib/python3.8/site-packages/werkzeug/serving.py", line 331, in execute
    application_iter = app(environ, start_response)
  File "/root/miniconda3/envs/USB/lib/python3.8/site-packages/tensorboard/backend/application.py", line 528, in __call__
    return self._app(environ, start_response)
  File "/root/miniconda3/envs/USB/lib/python3.8/site-packages/tensorboard/backend/application.py", line 569, in wrapper
    return wsgi_app(environ, start_response)
  File "/root/miniconda3/envs/USB/lib/python3.8/site-packages/tensorboard/backend/security_validator.py", line 91, in __call__
    return self._application(environ, start_response_proxy)
  File "/root/miniconda3/envs/USB/lib/python3.8/site-packages/tensorboard/backend/path_prefix.py", line 68, in __call__
    return self._application(environ, start_response)
  File "/root/miniconda3/envs/USB/lib/python3.8/site-packages/tensorboard/backend/experiment_id.py", line 73, in __call__
    return self._application(environ, start_response)
  File "/root/miniconda3/envs/USB/lib/python3.8/site-packages/tensorboard/backend/empty_path_redirect.py", line 43, in __call__
    return self._application(environ, start_response)
  File "/root/miniconda3/envs/USB/lib/python3.8/site-packages/tensorboard/backend/client_feature_flags.py", line 55, in __call__
    return self._application(environ, start_response)
  File "/root/miniconda3/envs/USB/lib/python3.8/site-packages/tensorboard/backend/auth_context_middleware.py", line 38, in __call__
    return self._application(environ, start_response)
  File "/root/miniconda3/envs/USB/lib/python3.8/site-packages/tensorboard/backend/application.py", line 551, in _route_request
    return self.exact_routes[clean_path](environ, start_response)
  File "/root/miniconda3/envs/USB/lib/python3.8/site-packages/werkzeug/wrappers/request.py", line 190, in application
    resp = f(*args[:-2] + (request,))
  File "/root/miniconda3/envs/USB/lib/python3.8/site-packages/tensorboard/plugins/hparams/hparams_plugin.py", line 122, in get_experiment_route
    json_format.MessageToJson(
TypeError: MessageToJson() got an unexpected keyword argument 'including_default_value_fields'
